ERROR 2017-06-28 21:30:55,475 exception 23405 140227390654208 Internal Server Error: /teamstore/login/
Traceback (most recent call last):
  File "/home/jonathan/staging_teamstore/env/lib/python3.5/site-packages/django/db/backends/base/base.py", line 199, in ensure_connection
    self.connect()
  File "/home/jonathan/staging_teamstore/env/lib/python3.5/site-packages/django/db/backends/base/base.py", line 171, in connect
    self.connection = self.get_new_connection(conn_params)
  File "/home/jonathan/staging_teamstore/env/lib/python3.5/site-packages/django/db/backends/postgresql/base.py", line 176, in get_new_connection
    connection = Database.connect(**conn_params)
  File "/home/jonathan/staging_teamstore/env/lib/python3.5/site-packages/psycopg2/__init__.py", line 164, in connect
    conn = _connect(dsn, connection_factory=connection_factory, async=async)
psycopg2.OperationalError: FATAL:  password authentication failed for user "saleor"
FATAL:  password authentication failed for user "saleor"


The above exception was the direct cause of the following exception:

Traceback (most recent call last):
  File "/home/jonathan/staging_teamstore/env/lib/python3.5/site-packages/django/core/handlers/exception.py", line 42, in inner
    response = get_response(request)
  File "/home/jonathan/staging_teamstore/env/lib/python3.5/site-packages/django/core/handlers/base.py", line 249, in _legacy_get_response
    response = self._get_response(request)
  File "/home/jonathan/staging_teamstore/env/lib/python3.5/site-packages/django/core/handlers/base.py", line 187, in _get_response
    response = self.process_exception_by_middleware(e, request)
  File "/home/jonathan/staging_teamstore/env/lib/python3.5/site-packages/django/core/handlers/base.py", line 185, in _get_response
    response = wrapped_callback(request, *callback_args, **callback_kwargs)
  File "/home/jonathan/staging_teamstore/env/lib/python3.5/site-packages/django/utils/decorators.py", line 149, in _wrapped_view
    response = view_func(request, *args, **kwargs)
  File "/home/jonathan/staging_teamstore/env/lib/python3.5/site-packages/django/views/decorators/cache.py", line 57, in _wrapped_view_func
    response = view_func(request, *args, **kwargs)
  File "./saleor/teamstore/views.py", line 54, in login
    return render(request, template_name, {'form': form})
  File "/home/jonathan/staging_teamstore/env/lib/python3.5/site-packages/django/shortcuts.py", line 30, in render
    content = loader.render_to_string(template_name, context, request, using=using)
  File "/home/jonathan/staging_teamstore/env/lib/python3.5/site-packages/django/template/loader.py", line 68, in render_to_string
    return template.render(context, request)
  File "/home/jonathan/staging_teamstore/env/lib/python3.5/site-packages/django/template/backends/django.py", line 66, in render
    return self.template.render(context)
  File "/home/jonathan/staging_teamstore/env/lib/python3.5/site-packages/django/template/base.py", line 206, in render
    with context.bind_template(self):
  File "/usr/lib/python3.5/contextlib.py", line 59, in __enter__
    return next(self.gen)
  File "/home/jonathan/staging_teamstore/env/lib/python3.5/site-packages/django/template/context.py", line 236, in bind_template
    updates.update(processor(self.request))
  File "./saleor/cart/context_processors.py", line 7, in cart_counter
    cart = get_cart_from_request(request)
  File "./saleor/cart/utils.py", line 180, in get_cart_from_request
    cart = get_anonymous_cart_from_token(token, cart_queryset)
  File "./saleor/cart/utils.py", line 143, in get_anonymous_cart_from_token
    return cart_queryset.open().filter(token=token, user=None).first()
  File "/home/jonathan/staging_teamstore/env/lib/python3.5/site-packages/django/db/models/query.py", line 556, in first
    objects = list((self if self.ordered else self.order_by('pk'))[:1])
  File "/home/jonathan/staging_teamstore/env/lib/python3.5/site-packages/django/db/models/query.py", line 256, in __iter__
    self._fetch_all()
  File "/home/jonathan/staging_teamstore/env/lib/python3.5/site-packages/django/db/models/query.py", line 1087, in _fetch_all
    self._result_cache = list(self.iterator())
  File "/home/jonathan/staging_teamstore/env/lib/python3.5/site-packages/django/db/models/query.py", line 54, in __iter__
    results = compiler.execute_sql()
  File "/home/jonathan/staging_teamstore/env/lib/python3.5/site-packages/django/db/models/sql/compiler.py", line 833, in execute_sql
    cursor = self.connection.cursor()
  File "/home/jonathan/staging_teamstore/env/lib/python3.5/site-packages/django/db/backends/base/base.py", line 231, in cursor
    cursor = self.make_debug_cursor(self._cursor())
  File "/home/jonathan/staging_teamstore/env/lib/python3.5/site-packages/django/db/backends/base/base.py", line 204, in _cursor
    self.ensure_connection()
  File "/home/jonathan/staging_teamstore/env/lib/python3.5/site-packages/django/db/backends/base/base.py", line 199, in ensure_connection
    self.connect()
  File "/home/jonathan/staging_teamstore/env/lib/python3.5/site-packages/django/db/utils.py", line 94, in __exit__
    six.reraise(dj_exc_type, dj_exc_value, traceback)
  File "/home/jonathan/staging_teamstore/env/lib/python3.5/site-packages/django/utils/six.py", line 685, in reraise
    raise value.with_traceback(tb)
  File "/home/jonathan/staging_teamstore/env/lib/python3.5/site-packages/django/db/backends/base/base.py", line 199, in ensure_connection
    self.connect()
  File "/home/jonathan/staging_teamstore/env/lib/python3.5/site-packages/django/db/backends/base/base.py", line 171, in connect
    self.connection = self.get_new_connection(conn_params)
  File "/home/jonathan/staging_teamstore/env/lib/python3.5/site-packages/django/db/backends/postgresql/base.py", line 176, in get_new_connection
    connection = Database.connect(**conn_params)
  File "/home/jonathan/staging_teamstore/env/lib/python3.5/site-packages/psycopg2/__init__.py", line 164, in connect
    conn = _connect(dsn, connection_factory=connection_factory, async=async)
django.db.utils.OperationalError: FATAL:  password authentication failed for user "saleor"
FATAL:  password authentication failed for user "saleor"

ERROR 2017-06-29 10:14:31,650 exception 23405 140227390654208 Internal Server Error: /teamstore/login/
Traceback (most recent call last):
  File "/home/jonathan/staging_teamstore/env/lib/python3.5/site-packages/django/db/backends/base/base.py", line 199, in ensure_connection
    self.connect()
  File "/home/jonathan/staging_teamstore/env/lib/python3.5/site-packages/django/db/backends/base/base.py", line 171, in connect
    self.connection = self.get_new_connection(conn_params)
  File "/home/jonathan/staging_teamstore/env/lib/python3.5/site-packages/django/db/backends/postgresql/base.py", line 176, in get_new_connection
    connection = Database.connect(**conn_params)
  File "/home/jonathan/staging_teamstore/env/lib/python3.5/site-packages/psycopg2/__init__.py", line 164, in connect
    conn = _connect(dsn, connection_factory=connection_factory, async=async)
psycopg2.OperationalError: FATAL:  password authentication failed for user "saleor"
FATAL:  password authentication failed for user "saleor"


The above exception was the direct cause of the following exception:

Traceback (most recent call last):
  File "/home/jonathan/staging_teamstore/env/lib/python3.5/site-packages/django/core/handlers/exception.py", line 42, in inner
    response = get_response(request)
  File "/home/jonathan/staging_teamstore/env/lib/python3.5/site-packages/django/core/handlers/base.py", line 249, in _legacy_get_response
    response = self._get_response(request)
  File "/home/jonathan/staging_teamstore/env/lib/python3.5/site-packages/django/core/handlers/base.py", line 187, in _get_response
    response = self.process_exception_by_middleware(e, request)
  File "/home/jonathan/staging_teamstore/env/lib/python3.5/site-packages/django/core/handlers/base.py", line 185, in _get_response
    response = wrapped_callback(request, *callback_args, **callback_kwargs)
  File "/home/jonathan/staging_teamstore/env/lib/python3.5/site-packages/django/utils/decorators.py", line 149, in _wrapped_view
    response = view_func(request, *args, **kwargs)
  File "/home/jonathan/staging_teamstore/env/lib/python3.5/site-packages/django/views/decorators/cache.py", line 57, in _wrapped_view_func
    response = view_func(request, *args, **kwargs)
  File "./saleor/teamstore/views.py", line 54, in login
    return render(request, template_name, {'form': form})
  File "/home/jonathan/staging_teamstore/env/lib/python3.5/site-packages/django/shortcuts.py", line 30, in render
    content = loader.render_to_string(template_name, context, request, using=using)
  File "/home/jonathan/staging_teamstore/env/lib/python3.5/site-packages/django/template/loader.py", line 68, in render_to_string
    return template.render(context, request)
  File "/home/jonathan/staging_teamstore/env/lib/python3.5/site-packages/django/template/backends/django.py", line 66, in render
    return self.template.render(context)
  File "/home/jonathan/staging_teamstore/env/lib/python3.5/site-packages/django/template/base.py", line 206, in render
    with context.bind_template(self):
  File "/usr/lib/python3.5/contextlib.py", line 59, in __enter__
    return next(self.gen)
  File "/home/jonathan/staging_teamstore/env/lib/python3.5/site-packages/django/template/context.py", line 236, in bind_template
    updates.update(processor(self.request))
  File "./saleor/cart/context_processors.py", line 7, in cart_counter
    cart = get_cart_from_request(request)
  File "./saleor/cart/utils.py", line 180, in get_cart_from_request
    cart = get_anonymous_cart_from_token(token, cart_queryset)
  File "./saleor/cart/utils.py", line 143, in get_anonymous_cart_from_token
    return cart_queryset.open().filter(token=token, user=None).first()
  File "/home/jonathan/staging_teamstore/env/lib/python3.5/site-packages/django/db/models/query.py", line 556, in first
    objects = list((self if self.ordered else self.order_by('pk'))[:1])
  File "/home/jonathan/staging_teamstore/env/lib/python3.5/site-packages/django/db/models/query.py", line 256, in __iter__
    self._fetch_all()
  File "/home/jonathan/staging_teamstore/env/lib/python3.5/site-packages/django/db/models/query.py", line 1087, in _fetch_all
    self._result_cache = list(self.iterator())
  File "/home/jonathan/staging_teamstore/env/lib/python3.5/site-packages/django/db/models/query.py", line 54, in __iter__
    results = compiler.execute_sql()
  File "/home/jonathan/staging_teamstore/env/lib/python3.5/site-packages/django/db/models/sql/compiler.py", line 833, in execute_sql
    cursor = self.connection.cursor()
  File "/home/jonathan/staging_teamstore/env/lib/python3.5/site-packages/django/db/backends/base/base.py", line 231, in cursor
    cursor = self.make_debug_cursor(self._cursor())
  File "/home/jonathan/staging_teamstore/env/lib/python3.5/site-packages/django/db/backends/base/base.py", line 204, in _cursor
    self.ensure_connection()
  File "/home/jonathan/staging_teamstore/env/lib/python3.5/site-packages/django/db/backends/base/base.py", line 199, in ensure_connection
    self.connect()
  File "/home/jonathan/staging_teamstore/env/lib/python3.5/site-packages/django/db/utils.py", line 94, in __exit__
    six.reraise(dj_exc_type, dj_exc_value, traceback)
  File "/home/jonathan/staging_teamstore/env/lib/python3.5/site-packages/django/utils/six.py", line 685, in reraise
    raise value.with_traceback(tb)
  File "/home/jonathan/staging_teamstore/env/lib/python3.5/site-packages/django/db/backends/base/base.py", line 199, in ensure_connection
    self.connect()
  File "/home/jonathan/staging_teamstore/env/lib/python3.5/site-packages/django/db/backends/base/base.py", line 171, in connect
    self.connection = self.get_new_connection(conn_params)
  File "/home/jonathan/staging_teamstore/env/lib/python3.5/site-packages/django/db/backends/postgresql/base.py", line 176, in get_new_connection
    connection = Database.connect(**conn_params)
  File "/home/jonathan/staging_teamstore/env/lib/python3.5/site-packages/psycopg2/__init__.py", line 164, in connect
    conn = _connect(dsn, connection_factory=connection_factory, async=async)
django.db.utils.OperationalError: FATAL:  password authentication failed for user "saleor"
FATAL:  password authentication failed for user "saleor"

